---
layout: post
title: 'day15笔记-异常处理'
description: Python基础
tag: 博客
---   
## day14 回顾
### 模块和包
    import 语句
    示例:
      import math
      import mypack.games.contra
      math.xx
      mypack.games.contra.xx

    from import 语句
    示例:
      from math import sin

      sin()  # 不需要加模块名或包的路径
    from import * 语句
      同上

### sys模块
    sys.path
    sys.version
    sys.modules
    sys.argv
    sys.exit()  # 退出程序
    自定义
      xxx.py
    全局变量 ---> 属性
    预置属性
      __doc__属性(当前模块的文档字符串)
      __file__属性(绑定路径)
      __name__属性(用来绑定模块名,区分主模块和非主模块)
    from import * 语句导入
    　　__all__ = ['aaa', 'bbb']
    　　_xxx = 1000  # 隐藏属性

随机模块 random

### 包

    __init__.py
    __all__列表一定要在__init__.py
    包的导入
      绝对导入
        from mypack.games.contra import *
      相对导入
        from .menu import show_menu
        from ..xx import yy
      搜索路径:
        当前路径
        sys.path 指定路径


## day15笔记
### 异常 exception
    什么是错误
      错误是指由于逻辑或语法等导致一个程序无法正常执行的问题

    什么是异常
      异常是指程序出错时标识的一种状态
      当异常发生时,程序不会再向下执行,而转去调用此函数的地方待处理此错误并恢复为正常状态
      作用:
        用作信号,通知上层调用者有错误产生需要处理

### try语句
### try-except语句
    语法:
      try:
          可能出发异常的语法
      except 错误类型1 [as 变量1]:
          异常处理语句1
      except 错误类型2 [as 变量2]:
          异常处理语句2
      except (错误类型3, 错误类型4):
          异常处理语句3
      ...
      except:
          异常处理语句other
      else:
          未发生异常语句
      finally:
          最终语句
    作用:
      尝试捕获异常(接受异常通知),将程序转为正常状态并继承执行
    语法说明:
      as 子句是用于绑定错误对象的变量,可以省略
      except 子句可以有一个或多个,但至少要有一个
      else 子句最多只能有一个,也可以省略不写
      finally 子句最多只能有一个,也可以省略不写
    注:
      int不能作为错误类型
    示例:
      # try_except.py

        def div_apple(n):
            print('%d个苹果您想分给几个人?' % n)
            s = input('请输入人数:')
            cnt = int(s)  # <<- 可能触发ValueError错误进入异常
            result = n / cnt  # <<-- 可能触发ZeroDivisionError错误
            print('每个人分了', result, '个苹果')
        try:
            div_apple(10)
            print('分苹果完成')
        except ValueError as err:
            print('错误的值是:', err)  # err绑定错误对象
        except (ValueError, ZeroDivisionError):
            print('分苹果失败')
        except:
            print('收到除上述两种类型以外的错误通知')
        else:  # 只有在try没有错误时才会执行
            print('在当前try语句内部,没有发生任何异常,程序走正常流程')
        finally:
            # finally 子句的语句无论是正常流程还是异常流程都会被执行
            print('我这条语句一定会执行的')

        print("程序正常退出")

### 练习
    1. 写一个函数 get_score() 来获取学生输入的成绩(0~100的整数),输入如果出现异常,则让此函数返回0,否则返回用户输入的成绩
    def get_score():
        s = int(input('请输入学生的成绩:'))
        if 0 <= s <= 100:
            return s
        else:
            return 0
      # 方法1,在调用的地方加入异常处理语句,然后进行处理
    try:
        score = get_score()
    except ValueError:
        score = 0  # 如果输入不合法,将成绩置零
    print('学生的成绩是:', score)


    # 方法2,在函数内部有可能抛出异常的函数加上try-except语句
    def get_score():
        try:
            s = int(input('请输入学生的成绩:'))
        except ValueError:
            return 0
        if 0 <= s <= 100:
            return s
        else:
            return 0

    score = get_score()
    print('学生的成绩是:', score)

    注:
      try-except语句也可以放在函数内部使用

[Python全部的异常类型](/html//Python全部的异常类型.html)

### try-finally语句
    语法:
      try:
        可能触发异常的语句
      finally:
        最终语句
    说明:
      finally 子句不可以省略
      一定不存在except子句
    作用:
      通常用try-finally语句来做触发异常时必须要处理的事情,无论异常是否发生,finally子句都会被执行
      try-finally 语句不会改变程序的(正常/异常状态)
    示例:
      # try_finally.py

      def fry_egg():
          print('打开天然气...')
          try:
              count = int(input('请输入鸡蛋个数:'))
              print('完成煎鸡蛋,共煎了%d个鸡蛋!' % count)
          finally:
              print('关闭天然气')
      try:
          fry_egg()
      except:
          print('程序出现过异常,已转为正常状态')

      print('程序正常退出')

    示例2:
      # try_finally_test.py
      x = 100
      y = 200
      try:
          save_x = x
          save_y = y
          try:
              x = int(input('请输入x:'))
              y = int(input('请输入y:'))
              print(x, y)  # 用x, y当前值来调用和打印
          finally:  # x, y恢复为原有数据
              x = save_x
              y = save_y
      except:
          pass
      print(x, y)  # x, y原始数据

### try语句嵌套
    try语句嵌套是指一个try语句嵌套在另一个try语句中

    示例:
      # try_embed.py

      # 此示例示意try语句嵌套,在内层的try语句如果已经把状态转为正常状态则外层的try语句将收不到错误通知
      try:
          try:
              n = int(input('请输入整数:'))
          except ValueError:
              print('内层try语句内出现值错误,已处理并转为正常状态')
          else:
              print('内层try语句没有出现异常')
      except:
          print('外层try语句接收到异常通知,已处理并转为正常状态')
      else:
          print('外层try语句没有出现异常')

### raise 语句
    作用:
      触发一个错误,让程序进入异常状态
      发送错误通知给调用者
    语法:
      raise 异常类型
      或
      rais 异常对象
      或
      rais  # 重新触发上一次异常
    示例:
      # raise.py

      def make_except():
          print('开始')
          # raise ValueError  # 故意发送一个错误通知
          e = ValueError('这是故意制作的一个错误')
          raise e

          print('结束')
      try:
          make_except()
      except ValueError as err:
          print('make_except 发出了ValueError类型的错误,已捕获')
          # 错误的原因获得
          print('错误的原因是:', err)

      print('程序结束')


    示例2:
      # raise2.py
      def make_except():
          print('开始 make_except')
          raise ValueError('我的一个值错误!')
          print('结束...')

      def get_except():
          try:
              make_except()
          except ValueError as err:
              print('错误的值是:', err)
              raise  # 重新触发刚收到的错误 等同于raise err

      try:
          get_except()
      except ValueError as err:
          print('get_except内部发生值错误!', err)

      print('程序结束')

### 练习
    写一个函数 get_age() 用来获取一个人的年龄信息
      此函数规定用户只能输入1~140之间的整数,如果用户输入其它的数则直接触发ValueError类型的错误来通知调用者

    def get_age():
        ...
    try:
        age = get_age()
        print('用户输入的年龄是:', age)
    except ValueError as err:
        print('用户输入的不是1~140的整数,获取年龄失败!')

    答:
    def get_age():
        ag = int(input('请输入年龄(1~140):'))
        if ag < 1 or ag > 140:
            raise ValueError('值不在1~140之间')
        else:
            return ag
    try:
        age = get_age()
        print('用户输入的年龄是:', age)
    except ValueError as err:
        print('用户输入的不是1~140的整数,获取年龄失败!', err)

### assert 语句(断言语句)
    语法:
      assert 真值表达式, 错误数据(通常是字符串)
    作用:
      当真值表达式为False时,用错误数据创建一个AssertionError类型的错误raise出去,并进入异常状态
    等同于:
      if 真值表达式 == False:
          raise AssertionError(错误数据)
    示例:
      # assert.py

      # 此示例示意asset语句的用法
      def get_score():
          s = int(input('请输入学生成绩(0~100):'))
          assert 0 <= s <= 100, '成绩超出范围!!!'
          return s

      try:
          score = get_score()
          print('学生的成绩为:', score)
      except ValueError:
          print('用户输入的数字不能转为整数...')
      except AssertionError:
          print('用户输入的整数不在0~100之间...')

## 为什么要用异常处理机制?
   在程序调用层数较深时,向主函数传递错误信息需要层层return,返回比较麻烦,所以用异常处理机制

### 今日练习
    1. 一个球从100米高空落下,每次落地后反弹高度是原高度的一半,再落下
      1) 写程序算出球在第10次落地后反弹高度是多少?
      2) 打印出共经过了多少米的路程
    2. 分解质因数: 输入一个正整数,分解质因数:
      如输入:
        90
      则打印:
        '90=2*3*3*5'
        (质因数是指最小能被原数整除的素数(不包含1))
    3. 修改原学生信息管理程序,加入异常处理语句,让程序在任何情况下都能按逻辑正常执行
      如: 输入成绩和年龄时,如果用户输入非法字符串也不会导致程序崩溃

    答:
    1.
      def ball_fall(x):
          i = 0
          while i < 10:
              x /= 2
              i += 1
          print(x)

      def ball_m(y):
          s = 0
          while y != 0:
              s += y
              y /= 2
          print(s)

      ball_fall(100)
      ball_m(100)
    2.
      def is_prime(x):
          if x < 2:
              return False
          for i in range(2, x):
              if x % i == 0:
                  return False
          return True


      L = []  # 此列表用来存储质因数
      n = int(input('请输入一个正整数:'))
      number = n  # 保存原有的数

      # 判断如果n不为1则找质因数
      while n != 1:
          for i in range(2, n+1):  # 依次让n除以i,如果整除则i为质因数
              if n % i == 0 and is_prime(i):  # 可以不判断i为素数
                  L.append(i)
                  n = int(n / i)
                  break  # 查找当前一个质因数结束

      print(L)
      print(number, '=', '*'.join([str(x) for x in L]), sep='')
